<?xml version="1.0"?>
<robot xmlns:xacro="http://www.ros.org/wiki/xacro">

    <xacro:include filename="constants.xacro" />

    <xacro:macro name="wheel_link" params="prefix">
        <link name="${prefix}_wheel_link">
            <visual>
                <geometry>
                    <cylinder radius="${wheel_radius}" length="${wheel_length}" />
                </geometry>
                <origin xyz="0 0 0" rpy="${pi/2.0} 0 0" />
                <material name="grey" />
            </visual>
            <collision>
                <geometry>
                    <cylinder radius="${wheel_radius}" length="${wheel_length}" />
                </geometry>
                <origin xyz="0 0 0" rpy="${pi/2.0} 0 0" />
            </collision>
            <xacro:cylinder_inertia m="${wheel_weight_kgs}" r="${wheel_radius}" h="${wheel_length}" xyz="0 0 0" rpy="${pi/2.0} 0 0"/>
        </link>
    </xacro:macro>



    <xacro:macro name="create_wheel_and_joint" params="prefix x y">
        <xacro:wheel_link prefix="${prefix}"/>
        <joint name="base_${prefix}_wheel_joint" type="continuous">
            <parent link="base_link"/>
            <child link="${prefix}_wheel_link"/>
            <origin xyz="${x} ${y} 0" rpy="0 0 0"/>
            <axis xyz="0 1 0" /> 
        </joint>
    </xacro:macro>

    <xacro:create_wheel_and_joint prefix="left_back" x="${-wheel_offset_x}" y="${wheel_offset_y}" />
    <xacro:create_wheel_and_joint prefix="right_back" x="${-wheel_offset_x}" y="${-wheel_offset_y}" />
    <xacro:create_wheel_and_joint prefix="left_middle" x="0" y="${wheel_offset_y}" />
    <xacro:create_wheel_and_joint prefix="right_middle" x="0" y="${-wheel_offset_y}" />
    <xacro:create_wheel_and_joint prefix="left_front" x="${wheel_offset_x}" y="${wheel_offset_y}" />
    <xacro:create_wheel_and_joint prefix="right_front" x="${wheel_offset_x}" y="${-wheel_offset_y}" />

    <link name="base_link">
        <visual>
            <geometry>
                <box size="${base_length} ${base_width} ${base_height}" />
            </geometry>
            <origin xyz="0 0 ${base_origin_z}" rpy="0 0 0" />
            <material name="blue" />
        </visual>
        <collision>
            <geometry>
                <box size="${base_length} ${base_width} ${base_height}" />
            </geometry>
            <origin xyz="0 0 ${base_origin_z}" rpy="0 0 0" />
        </collision>
        <xacro:box_inertia m="${chasis_weight_kgs}" l="${base_length}" w="${base_width}" h="${base_height}" xyz="0 0 ${base_origin_z}" rpy="0 0 0"/>
    </link>

    <link name="base_footprint"></link>
    <joint name="base_base_footprint" type="fixed">
        <parent link="base_footprint"/>
        <child link="base_link"/>
        <origin xyz="0 0 ${wheel_radius}" rpy="0 0 0"/>
    </joint>
</robot>
