<?xml version="1.0" encoding="utf-8"?>
<!-- This URDF was automatically created by SolidWorks to URDF Exporter! Originally created by Stephen Brawner (brawner@gmail.com) 
     Commit Version: 1.6.0-4-g7f85cfe  Build Version: 1.6.7995.38578
     For more information, please see http://wiki.ros.org/sw_urdf_exporter -->
<robot
  name="mesh_test_11" xmlns:xacro="http://www.ros.org/wiki/xacro">
  <link
    name="chassis">
    <inertial>
      <origin
        xyz="0.0079174 -0.19192 0.11862"
        rpy="0 0 0" />
      <mass
        value="7.8336" />
      <inertia
        ixx="0.077724"
        ixy="0.00055232"
        ixz="-0.00012312"
        iyy="0.06667"
        iyz="0.0010223"
        izz="0.13451" />
    </inertial>
    <visual>
      <origin
        xyz="0 0 0"
        rpy="0 0 0" />
      <geometry>
        <mesh
          filename="package://sdrc_description/meshes/chassis.STL" />
      </geometry>
      <material
        name="">
        <color
          rgba="0.75294 0.75294 0.75294 1" />
      </material>
    </visual>
    <collision>
      <origin
        xyz="0 0 0"
        rpy="0 0 0" />
      <geometry>
        <mesh
          filename="package://sdrc_description/meshes/chassis.STL" />
      </geometry>
    </collision>
  </link>
  <link
    name="left_bogie_link">
    <inertial>
      <origin
        xyz="0.015875 -0.13783 -0.047232"
        rpy="0 0 0" />
      <mass
        value="0.5" />
      <inertia
        ixx="0.0021898"
        ixy="-4.4494E-08"
        ixz="-1.4435E-08"
        iyy="0.00027856"
        iyz="-0.00036761"
        izz="0.0020183" />
    </inertial>
    <visual>
      <origin
        xyz="0 0 0"
        rpy="0 0 0" />
      <geometry>
        <mesh
          filename="package://sdrc_description/meshes/left_bogie_link.STL" />
      </geometry>
      <material
        name="">
        <color
          rgba="1 1 1 1" />
      </material>
    </visual>
    <collision>
      <origin
        xyz="0 0 0"
        rpy="0 0 0" />
      <geometry>
        <mesh
          filename="package://sdrc_description/meshes/left_bogie_link.STL" />
      </geometry>
    </collision>
  </link>
  <joint
    name="left_bogie_joint"
    type="fixed">
    <origin
      xyz="-0.35 0 -0.022"
      rpy="0 0 0" />
    <parent
      link="chassis" />
    <child
      link="left_bogie_link" />
    <axis
      xyz="-1 0 0" />
  </joint>
  <link
    name="left_front_wheel_link">
    <inertial>
      <origin
        xyz="0.000155212043927988 -2.36124552174255E-05 4.13306403687641E-05"
        rpy="0 0 0" />
      <mass
        value="1.39" />
      <inertia
        ixx="0.001"
        ixy="0.000"
        ixz="0.000"
        iyy="0.001"
        iyz="0.000"
        izz="0.001" />
    </inertial>
    <visual>
      <origin
        xyz="0 0 0"
        rpy="0 0 0" />
      <geometry>
        <mesh
          filename="package://sdrc_description/meshes/left_front_wheel_link.STL" />
      </geometry>
      <material
        name="">
        <color
          rgba="0.792156862745098 0.819607843137255 0.933333333333333 1" />
      </material>
    </visual>
    <collision>
      <origin
        xyz="0 0 0"
        rpy="0 0 0" />
      <geometry>
        <mesh
          filename="package://sdrc_description/meshes/left_front_wheel_link.STL" />
      </geometry>
      <surface>
        <friction>
          <ode>
            <mu>100000.0</mu>
            <mu2>100000.0</mu2>
            <fdir1>0 0 0</fdir1>
            <slip1>0.0</slip1>
            <slip2>0.0</slip2>
          </ode>
          <contact>
            <ode>
              <soft_cfm>0</soft_cfm>
              <soft_erp>0.2</soft_erp>
              <kp>1e+5</kp>
              <kd>1</kd>
              <max_vel>0.01</max_vel>
              <!-- <min_depth>0.001</min_depth> -->
            </ode>
          </contact>
        </friction>
      </surface>
    </collision>
  </link>
  <joint
    name="left_front_wheel_joint"
    type="continuous">
    <origin
      xyz="-0.026 -0.435 -0.245"
      rpy="0 0 0" />
    <parent
      link="left_bogie_link" />
    <child
      link="left_front_wheel_link" />
    <axis
      xyz="1 0 0" />
  </joint>
  <link
    name="left_rocker_link">
    <inertial>
      <origin
        xyz="-4.20561563853061E-05 0.0320692844249238 -0.0458110093782014"
        rpy="0 0 0" />
      <mass
        value="0.45" />
      <inertia
        ixx="0.000557359425591044"
        ixy="3.94579138177333E-08"
        ixz="-1.73611323725284E-07"
        iyy="0.000207816779409454"
        iyz="-1.29419652457806E-05"
        izz="0.000444163243659817" />
    </inertial>
    <visual>
      <origin
        xyz="0 0 0"
        rpy="0 0 0" />
      <geometry>
        <mesh
          filename="package://sdrc_description/meshes/left_rocker_link.STL" />
      </geometry>
      <material
        name="">
        <color
          rgba="0.898039215686275 0.917647058823529 0.929411764705882 1" />
      </material>
    </visual>
    <collision>
      <origin
        xyz="0 0 0"
        rpy="0 0 0" />
      <geometry>
        <mesh
          filename="package://sdrc_description/meshes/left_rocker_link.STL" />
      </geometry>
    </collision>
  </link>
  <joint
    name="left_rocker_joint"
    type="fixed">
    

    <origin
      xyz="-0.022 0.22 -0.059"
      rpy="0 0 0" />
    <parent
      link="left_bogie_link" />
    <child
      link="left_rocker_link" />
    <axis
      xyz="-1 0 0" />
  </joint>
  <link
    name="left_rear_wheel_link">
    <inertial>
      <origin
        xyz="0.00011831 -5.6559E-06 -2.1325E-05"
        rpy="0 0 0" />
      <mass
        value="1.39" />
      <inertia
        ixx="0.001"
        ixy="0.000"
        ixz="0.000"
        iyy="0.001"
        iyz="0.000"
        izz="0.001" />
    </inertial>
    <visual>
      <origin
        xyz="0 0 0"
        rpy="0 0 0" />
      <geometry>
        <mesh
          filename="package://sdrc_description/meshes/left_rear_wheel_link.STL" />
      </geometry>
      <material
        name="">
        <color
          rgba="0.79216 0.81961 0.93333 1" />
      </material>
    </visual>
    <collision>
      <origin
        xyz="0 0 0"
        rpy="0 0 0" />
      <geometry>
        <mesh
          filename="package://sdrc_description/meshes/left_rear_wheel_link.STL" />
      </geometry>
      <surface>
        <friction>
          <ode>
            <mu>100000.0</mu>
            <mu2>100000.0</mu2>
            <fdir1>0 0 0</fdir1>
            <slip1>0.0</slip1>
            <slip2>0.0</slip2> 
          </ode>
        </friction>
        <contact>
            <ode>
              <soft_cfm>0</soft_cfm>
              <soft_erp>0.2</soft_erp>
              <kp>1e+5</kp>
              <kd>1</kd>
              <max_vel>0.01</max_vel>
              <!-- <min_depth>0.001</min_depth> -->
            </ode>
          </contact>
      </surface>
    </collision>
  </link>
  <joint
    name="left_rear_wheel_joint"
    type="continuous">
    <origin
      xyz="-0.042 0.216 -0.193"
      rpy="0 0 0" />
    <parent
      link="left_rocker_link" />
    <child
      link="left_rear_wheel_link" />
    <axis
      xyz="1 0 0" />
  </joint>
  <link
    name="left_middle_wheel_link">
    <inertial>
      <origin
        xyz="0.00011831 -6.0648E-06 -2.1149E-05"
        rpy="0 0 0" />
      <mass
        value="1.39" />
      <inertia
        ixx="0.001"
        ixy="0.000"
        ixz="0.000"
        iyy="0.001"
        iyz="0.000"
        izz="0.001" />
    </inertial>
    <visual>
      <origin
        xyz="0 0 0"
        rpy="0 0 0" />
      <geometry>
        <mesh
          filename="package://sdrc_description/meshes/left_middle_wheel_link.STL" />
      </geometry>
      <material
        name="">
        <color
          rgba="0.79216 0.81961 0.93333 1" />
      </material>
    </visual>
    <collision>
      <origin
        xyz="0 0 0"
        rpy="0 0 0" />
      <geometry>
        <mesh
          filename="package://sdrc_description/meshes/left_middle_wheel_link.STL" />
      </geometry>
      <surface>
        <friction>
          <ode>
            <mu>100000.0</mu>
            <mu2>100000.0</mu2>
            <fdir1>0 0 0</fdir1>
            <slip1>0.0</slip1>
            <slip2>0.0</slip2> 
          </ode>
        </friction>
        <contact>
            <ode>
              <soft_cfm>0</soft_cfm>
              <soft_erp>0.2</soft_erp>
              <kp>1e+5</kp>
              <kd>1</kd>
              <max_vel>0.01</max_vel>
              <!-- <min_depth>0.001</min_depth> -->
            </ode>
          </contact>
      </surface>
    </collision>
  </link>
  <joint
    name="left_middle_wheel_joint"
    type="continuous">
    <origin
      xyz="-0.042 -0.22 -0.19"
      rpy="0 0 0" />
    <parent
      link="left_rocker_link" />
    <child
      link="left_middle_wheel_link" />
    <axis
      xyz="1 0 0" />
  </joint>
  <link
    name="right_bogie_link">
    <inertial>
      <origin
        xyz="0.015875 0.13783 -0.047232"
        rpy="0 0 0" />
      <mass
        value="0.5" />
      <inertia
        ixx="0.0021898"
        ixy="-4.4494E-08"
        ixz="-1.4435E-08"
        iyy="0.00027856"
        iyz="-0.00036761"
        izz="0.0020183" />
    </inertial>
    <visual>
      <origin
        xyz="0 0 0"
        rpy="0 0 0" />
      <geometry>
        <mesh
          filename="package://sdrc_description/meshes/right_bogie_link.STL" />
      </geometry>
      <material
        name="">
        <color
          rgba="1 1 1 1" />
      </material>
    </visual>
    <collision>
      <origin
        xyz="0 0 0"
        rpy="0 0 0" />
      <geometry>
        <mesh
          filename="package://sdrc_description/meshes/right_bogie_link.STL" />
      </geometry>
    </collision>
  </link>
  <joint
    name="right_bogie_joint"
    type="fixed">
    <origin
      xyz="0.35 0 -0.022"
      rpy="0 0 0" />
    <parent
      link="chassis" />
    <child
      link="right_bogie_link" />
    <axis
      xyz="-1 0 0" />
  </joint>
  <link
    name="right_rocker_link">
    <inertial>
      <origin
        xyz="4.20751756289306E-05 -0.0320692797825197 -0.0458110120936045"
        rpy="0 0 0" />
      <mass
        value="0.45" />
      <inertia
        ixx="0.000557359425591044"
        ixy="3.94579138177333E-08"
        ixz="-1.73611323725284E-07"
        iyy="0.000207816779409454"
        iyz="-1.29419652457806E-05"
        izz="0.000444163243659817" />
    </inertial>
    <visual>
      <origin
        xyz="0 0 0"
        rpy="0 0 0" />
      <geometry>
        <mesh
          filename="package://sdrc_description/meshes/right_rocker_link.STL" />
      </geometry>
      <material
        name="">
        <color
          rgba="0.898039215686275 0.917647058823529 0.929411764705882 1" />
      </material>
    </visual>
    <collision>
      <origin
        xyz="0 0 0"
        rpy="0 0 0" />
      <geometry>
        <mesh
          filename="package://sdrc_description/meshes/right_rocker_link.STL" />
      </geometry>
    </collision>
  </link>
  <joint
    name="right_rocker_joint"
    type="fixed">
    <origin
      xyz="0.022 0.22 -0.059"
      rpy="0 0 0" />
    <parent
      link="right_bogie_link" />
    <child
      link="right_rocker_link" />
    <axis
      xyz="-1 0 0" />
  </joint>
  <link
    name="right_middle_wheel_link">
    <inertial>
      <origin
        xyz="-0.000136764013834112 -4.17413270043845E-07 -3.58308653414241E-07"
        rpy="0 0 0" />
      <mass
        value="1.39" />
      <inertia
        ixx="0.001"
        ixy="0.000"
        ixz="0.000"
        iyy="0.001"
        iyz="0.000"
        izz="0.001" />
    </inertial>
    <visual>
      <origin
        xyz="0 0 0"
        rpy="0 0 0" />
      <geometry>
        <mesh
          filename="package://sdrc_description/meshes/right_middle_wheel_link.STL" />
      </geometry>
      <material
        name="">
        <color
          rgba="0.792156862745098 0.819607843137255 0.933333333333333 1" />
      </material>
    </visual>
    <collision>
      <origin
        xyz="0 0 0"
        rpy="0 0 0" />
      <geometry>
        <mesh
          filename="package://sdrc_description/meshes/right_middle_wheel_link.STL" />
      </geometry>
      <surface>
        <friction>
          <ode>
            <mu>100000.0</mu>
            <mu2>100000.0</mu2>
            <fdir1>0 0 0</fdir1>
            <slip1>0.0</slip1>
            <slip2>0.0</slip2>   
          </ode>
        </friction>
        <contact>
            <ode>
              <soft_cfm>0</soft_cfm>
              <soft_erp>0.2</soft_erp>
              <kp>1e+5</kp>
              <kd>1</kd>
              <max_vel>0.01</max_vel>
              <!-- <min_depth>0.001</min_depth> -->
            </ode>
          </contact>
      </surface>
    </collision>
  </link>
  <joint
    name="right_middle_wheel_joint"
    type="continuous">
    <origin
      xyz="0.042 -0.22 -0.19"
      rpy="0 0 0" />
    <parent
      link="right_rocker_link" />
    <child
      link="right_middle_wheel_link" />
    <axis
      xyz="1 0 0" />
  </joint>
  <link
    name="right_rear_wheel_link">
    <inertial>
      <origin
        xyz="-0.000136764013806079 -3.97276728181239E-09 -5.47524751814965E-07"
        rpy="0 0 0" />
      <mass
        value="1.39" />
      <inertia
        ixx="0.001"
        ixy="0.000"
        ixz="0.000"
        iyy="0.001"
        iyz="0.000"
        izz="0.001" />
    </inertial>
    <visual>
      <origin
        xyz="0 0 0"
        rpy="0 0 0" />
      <geometry>
        <mesh
          filename="package://sdrc_description/meshes/right_rear_wheel_link.STL" />
      </geometry>
      <material
        name="">
        <color
          rgba="0.792156862745098 0.819607843137255 0.933333333333333 1" />
      </material>
    </visual>
    <collision>
      <origin
        xyz="0 0 0"
        rpy="0 0 0" />
      <geometry>
        <mesh
          filename="package://sdrc_description/meshes/right_rear_wheel_link.STL" />
      </geometry>
      <surface>
        <friction>
          <ode>
            <mu>100000.0</mu>
            <mu2>100000.0</mu2>
            <fdir1>0 0 0</fdir1>
            <slip1>0.0</slip1>
            <slip2>0.0</slip2>   
          </ode>
        </friction>
        <contact>
            <ode>
              <soft_cfm>0</soft_cfm>
              <soft_erp>0.2</soft_erp>
              <kp>1e+5</kp>
              <kd>1</kd>
              <max_vel>0.01</max_vel>
              <!-- <min_depth>0.001</min_depth> -->
            </ode>
          </contact>
      </surface>
    </collision>
  </link>
  <joint
    name="right_rear_wheel_joint"
    type="continuous">
    <origin
      xyz="0.042 0.216 -0.193"
      rpy="0 0 0" />
    <parent
      link="right_rocker_link" />
    <child
      link="right_rear_wheel_link" />
    <axis
      xyz="1 0 0" />
  </joint>
  <link
    name="right_front_wheel_link">
    <inertial>
      <origin
        xyz="-0.000118164933657405 5.50144876632075E-06 -1.77910473420084E-06"
        rpy="0 0 0" />
      <mass
        value="1.39" />
      <inertia
        ixx="0.001"
        ixy="0.000"
        ixz="0.000"
        iyy="0.001"
        iyz="0.000"
        izz="0.001" />
    </inertial>
    <visual>
      <origin
        xyz="0 0 0"
        rpy="0 0 0" />
      <geometry>
        <mesh
          filename="package://sdrc_description/meshes/right_front_wheel_link.STL" />
      </geometry>
      <material
        name="">
        <color
          rgba="0.792156862745098 0.819607843137255 0.933333333333333 1" />
      </material>
    </visual>
    <collision>
      <origin
        xyz="0 0 0"
        rpy="0 0 0" />
      <geometry>
        <mesh
          filename="package://sdrc_description/meshes/right_front_wheel_link.STL" />
      </geometry>
      <surface>
        <friction>
          <ode>
            <mu>100000.0</mu>
            <mu2>100000.0</mu2>
            <fdir1>0 0 0</fdir1>
            <slip1>0.0</slip1>
            <slip2>0.0</slip2>  
          </ode>
        </friction>
        <contact>
            <ode>
              <soft_cfm>0</soft_cfm>
              <soft_erp>0.2</soft_erp>
              <kp>1e+5</kp>
              <kd>1</kd>
              <max_vel>0.01</max_vel>
              <!-- <min_depth>0.001</min_depth> -->
            </ode>
          </contact>
      </surface>
    </collision>
  </link>
  <joint
    name="right_front_wheel_joint"
    type="continuous">
    <origin
      xyz="0.026 -0.435 -0.245"
      rpy="0 0 0" />
    <parent
      link="right_bogie_link" />
    <child
      link="right_front_wheel_link" />
    <axis
      xyz="1 0 0" />
  </joint>

  <link name="base_link"></link>
  <joint name="base_base_link" type="fixed">
      <parent link="base_link"/>
      <child link="chassis"/>
      <origin xyz="0 0 0.35" rpy="0 0 ${pi / 2}"/>
  </joint>

  <joint name="base_footprint_joint" type="fixed">
      <parent link="base_link"/>
      <child link="base_footprint"/>
      <origin xyz="0 0 0" rpy="0 0 0"/>
  </joint>

  <link name="base_footprint"></link>
</robot>